Workbook

Sheet Salary Jan 2026
A1: Sno | B1: Location | C1: Company | D1: "Emp Code" | E1: Emp Name | F1: Designation | G1: Total Days | H1: Basic | I1: HRA | J1: Special Allowance | K1: Education Allowance | L1: Total | M1: PF | N1: Tax | O1: No of Working Days | P1: No of Leave | Q1: No of Leave deducted | R1: Basic Salary | S1: HRA | T1: Special Allowance | U1: Incentive | V1: Over time | W1: Travel Allowance | X1: Bonus | Y1: Cumulative Incentive | Z1: Green thanks | AA1: Education Allowance | AB1: Gross Salary | AC1: Loan opening | AD1: Loan Deducted | AE1: Loan Bal | AF1: PF | AG1: ESI | AH1: Advance | AI1: Lop | AJ1: Contribution | AK1: TDS | AL1: Other Deductions | AM1: Net Salary
A2: 3 | B2: Office | C2: NA | D2: Shi1878 | E2: ShivaramG S | F2: Finance Head | G2: 31 | H2: NA | I2: NA | J2: NA | K2: NA | L2: NA | M2: NA | N2: NA | R2: NA | S2: NA | T2: NA | V2: 0 | W2: 0 | X2: 0 | Y2: 0 | Z2: 0 | AA2: 0 | AB2: 0 | AC2: 0 | AD2: 0 | AE2: 0 | AF2: 0 | AG2: 0 | AH2: 0 | AI2: 0 | AJ2: 0 | AK2: 0 | AL2: 0 | AM2: 0
A3: 4 | B3: Office | C3: Igreen | D3: Cha1075 | E3: Ganesh Chandra Das | F3: Bore Path SpecialistÂ | G3: 31 | H3: 35500 | I3: 17750 | J3: 11750 | K3: 0 | L3: 65000 | M3: 1800 | N3: 0 | O3: 31 | P3: 0 | Q3: 0 | R3: 35500 | S3: 17750 | T3: 11750 | U3: ='[1]Jan 2026'!$F$19 -> 6000 | V3: 0 | W3: 0 | X3: 0 | Y3: 0 | AA3: 0 | AB3: =SUM(R3:AA3) -> 71000 | AC3: 0 | AD3: 0 | AE3: 0 | AF3: =IF(AB3-AI3>=15000, 1800) -> 1800 | AG3: =ROUNDUP(IF((AB3-AI3)>=21001,0,(AB3-AI3)*0.75%),0) -> 0 | AI3: =L3/G3*Q3 -> 0 | AJ3: 0 | AK3: 0 | AL3: =AC3*1%+AH3*1%+210 -> 210 | AM3: =AB3-AD3-AF3-AG3-AH3-AI3-AJ3-AK3-AL3 -> 68990
A4: 5 | B4: Office | C4: Igreen | D4: K1848 | E4: ParamasivamK | F4: Site Coordinator | G4: 31 | H4: 15000 | I4: 7500 | J4: 7500 | K4: 3000 | L4: 33000 | M4: 1800 | N4: 0 | O4: 30 | P4: 1 | Q4: 0 | R4: 15000 | S4: 7500 | T4: 7500 | U4: ='[1]Jan 2026'!$C$39 -> 1290 | W4: 3000 | X4: 0 | Y4: 0 | Z4: 6000 | AA4: 0 | AB4: =SUM(R4:AA4) -> 40290 | AC4: 10000 | AD4: 5000 | AE4: 5000 | AF4: =IF(AB4-AI4>=15000, 1800) -> 1800 | AG4: =ROUNDUP(IF((AB4-AI4)>=21001,0,(AB4-AI4)*0.75%),0) -> 0 | AI4: =L4/G4*Q4 -> 0 | AJ4: 0 | AK4: 0 | AL4: =AC4*1%+AH4*1%+210 -> 310 | AM4: =AB4-AD4-AF4-AG4-AH4-AI4-AJ4-AK4-AL4 -> 33180 | AO4: Bike service cost 6k given
A5: 6 | B5: Office | C5: Igreen | D5: Raj1634 | E5: SankarRaja | F5: Sr. Site Coordinator | G5: 31 | H5: 19500 | I5: 9750 | J5: 5750 | K5: 4000 | L5: 39000 | M5: 1800 | N5: 0 | O5: 24 | P5: 7 | Q5: 0 | R5: 19500 | S5: 9750 | T5: 5750 | U5: ='[1]Jan 2026'!$G$19 -> 2800 | W5: 4000 | X5: 0 | Y5: 0 | AA5: 0 | AB5: =SUM(R5:AA5) -> 41800 | AC5: 30000 | AD5: 5000 | AE5: =AC5-AD5 -> 25000 | AF5: =IF(AB5-AI5>=15000, 1800) -> 1800 | AG5: =ROUNDUP(IF((AB5-AI5)>=21001,0,(AB5-AI5)*0.75%),0) -> 0 | AI5: =L5/G5*Q5 -> 0 | AJ5: 0 | AK5: 0 | AL5: =AC5*1%+AH5*1%+210 -> 510 | AM5: =AB5-AD5-AF5-AG5-AH5-AI5-AJ5-AK5-AL5 -> 34490
A6: 9 | B6: Office | C6: IGREEN | D6: Aru1675 | E6: SivanArumugam | F6: Driver | G6: 31 | H6: 15500 | I6: 7750 | J6: 5750 | K6: 0 | L6: 29000 | M6: 1800 | N6: 0 | O6: 20 | P6: 11 | Q6: 9 | R6: 15500 | S6: 7750 | T6: 5750 | U6: 0 | V6: 0 | W6: 0 | X6: 0 | Y6: 0 | Z6: 0 | AA6: 0 | AB6: =SUM(R6:AA6) -> 29000 | AD6: 0 | AE6: =AC6-AD6 -> 0 | AF6: 1800 | AG6: 0 | AH6: 1219 | AI6: =L6/G6*Q6 -> 8419.3548 | AJ6: 0 | AK6: 0 | AL6: =AC6*1%+AH6*1%+210 -> 222.19 | AM6: =AB6-AD6-AF6-AG6-AH6-AI6-AJ6-AK6-AL6 -> 17339.455 | AO6: 1000rs advance 219 recharge
A7: 8 | B7: Office | C7: Igreen | D7: She1264 | E7: Mazhar Shekh | F7: Operator | G7: 31 | H7: 26500 | I7: 13000 | J7: 11500 | K7: 2000 | L7: 53000 | M7: 1800 | N7: 0 | O7: 31 | P7: 0 | Q7: 0 | R7: 26500 | S7: 13000 | T7: 11500 | W7: 2000 | X7: 0 | Y7: 0 | Z7: 0 | AA7: 0 | AB7: =SUM(R7:AA7) -> 53000 | AC7: 10000 | AD7: 5000 | AE7: =AC7-AD7 -> 5000 | AF7: =IF(AB7-AI7>=15000, 1800) -> 1800 | AG7: 0 | AI7: =L7/G7*Q7 -> 0 | AJ7: 0 | AK7: 0 | AL7: =AC7*1%+210+5000 -> 5310 | AM7: =AB7-AD7-AF7-AG7-AH7-AI7-AJ7-AK7-AL7 -> 40890
A8: 9 | B8: Office | C8: Igreen Transfer | D8: C1952 | E8: LakshmananC | F8: Welder | G8: 31 | H8: 10000 | I8: 5000 | J8: 5000 | K8: 3000 | L8: 23000 | M8: 0 | N8: 0 | O8: 31 | P8: 0 | Q8: 0 | R8: 10000 | S8: 5000 | T8: 5000 | W8: 3000 | X8: 0 | Y8: 0 | Z8: 0 | AA8: 0 | AB8: =SUM(R8:AA8) -> 23000 | AC8: =5000+5000 -> 10000 | AD8: 5000 | AE8: =AC8-AD8 -> 5000 | AF8: 0 | AG8: 0 | AI8: =L8/G8*Q8 -> 0 | AJ8: 0 | AK8: 0 | AL8: 100 | AM8: =AB8-AD8-AF8-AG8-AH8-AI8-AJ8-AK8-AL8 -> 17900 | AN8: Incentive added
A9: 10 | B9: Factory | C9: IGT Manufacturing | D9: P1780 | E9: Kannan P | F9: Trainee | G9: 31 | H9: 10000 | I9: 5000 | J9: 5000 | K9: 0 | L9: 20000 | M9: 1800 | N9: 0 | O9: 28.5 | P9: 2.5 | Q9: 1.5 | R9: 10000 | S9: 5000 | T9: 5000 | V9: ='Factory Overtime working'!F3 -> 2500 | W9: 0 | X9: 0 | Y9: 0 | AA9: 0 | AB9: =SUM(R9:AA9) -> 22500 | AC9: 0 | AD9: 0 | AE9: 0 | AF9: =IF(AB9-AI9>=15000, 1800) -> 1800 | AG9: 162 | AI9: =L9/G9*Q9 -> 967.74194 | AJ9: 0 | AK9: 0 | AL9: =AC9*1%+AH9*1%+210 -> 210 | AM9: =AB9-AD9-AF9-AG9-AH9-AI9-AJ9-AK9-AL9 -> 19360.258 | AN9: Salary advance 2k deducted
A10: 12 | B10: Office | C10: Igreen | D10: P1835 | E10: BalajiP | F10: Executive | G10: 31 | H10: 10000 | I10: 5000 | J10: 5000 | K10: 1000 | L10: 21000 | M10: 1800 | N10: 0 | O10: 30 | P10: 1 | Q10: 0 | R10: 10000 | S10: 5000 | T10: 5000 | W10: 0 | X10: 0 | Y10: 0 | Z10: 0 | AA10: 0 | AB10: =SUM(R10:AA10) -> 20000 | AC10: 9000 | AD10: 3000 | AE10: =AC10-AD10 -> 6000 | AF10: =IF(AB10-AI10>=15000, 1800) -> 1800 | AG10: =ROUNDUP(IF((AB10-AI10)>=21001,0,(AB10-AI10)*0.75%),0) -> 150 | AI10: =L10/G10*Q10 -> 0 | AJ10: 0 | AK10: 0 | AL10: =AC10*1%+AH10*1%+210 -> 300 | AM10: =AB10-AD10-AF10-AG10-AH10-AI10-AJ10-AK10-AL10 -> 14750 | AN10: 5000rs to be given in cahs | AO10: 5000 to be paid in cash , Leave to be discussed
A11: 13 | B11: Office | C11: Igreen | D11: R1275 | E11: DeepakR | F11: Relationship Manager | G11: 31 | H11: 22500 | I11: 11250 | J11: 11250 | K11: 4000 | L11: 49000 | M11: 1800 | N11: 0 | O11: 30 | P11: 1 | Q11: 0 | R11: 22500 | S11: 11250 | T11: 11250 | U11: ='[1]Jan 2026'!$E$33 -> 4097.16 | W11: 4000 | X11: 0 | Y11: 0 | Z11: 0 | AA11: 0 | AB11: =SUM(R11:AA11) -> 53097.16 | AC11: 0 | AD11: 0 | AE11: 0 | AF11: =IF(AB11-AI11>=15000, 1800) -> 1800 | AG11: =ROUNDUP(IF((AB11-AI11)>=21001,0,(AB11-AI11)*0.75%),0) -> 0 | AI11: =L11/G11*Q11 -> 0 | AJ11: 0 | AK11: 0 | AL11: =AC11*1%+AH11*1%+210 -> 210 | AM11: =AB11-AD11-AF11-AG11-AH11-AI11-AJ11-AK11-AL11 -> 51087.16
A12: 14 | B12: Factory | C12: IGT Manufacturing | D12: Sha1650 | E12: Sivarajan Shanmugam | F12: CNC Programmer | G12: 31 | H12: 18500 | I12: 9250 | J12: 9250 | K12: 0 | L12: 37000 | M12: 1800 | N12: 0 | O12: 30 | P12: 1 | Q12: 0 | R12: 18500 | S12: 9250 | T12: 9250 | V12: ='Factory Overtime working'!F4 -> 0 | W12: 0 | X12: 0 | Y12: 0 | Z12: 0 | AA12: 0 | AB12: =SUM(R12:AA12) -> 37000 | AC12: 0 | AD12: 0 | AE12: 0 | AF12: =IF(AB12-AI12>=15000, 1800) -> 1800 | AG12: =ROUNDUP(IF((AB12-AI12)>=21001,0,(AB12-AI12)*0.75%),0) -> 0 | AI12: =L12/G12*Q12 -> 0 | AJ12: 0 | AK12: 0 | AL12: =AC12*1%+AH12*1%+210 -> 210 | AM12: =AB12-AF12-AI12-AL12 -> 34990
A13: 15 | B13: Office | C13: Igreen Transfer | D13: Das1142 | E13: ShibuDas | F13: Driver | G13: 31 | H13: 12000 | I13: 6000 | J13: 6000 | K13: 1000 | L13: 25000 | M13: 0 | N13: 0 | O13: 31 | P13: 0 | Q13: 0 | R13: 12000 | S13: 6000 | T13: 6000 | U13: 0 | W13: 1000 | X13: 0 | Y13: 0 | Z13: 2000 | AA13: 0 | AB13: =SUM(R13:AA13) -> 27000 | AC13: 2000 | AD13: 2000 | AE13: =AC13-AD13 -> 0 | AF13: 0 | AG13: 0 | AI13: =L13/G13*Q13 -> 0 | AJ13: 0 | AK13: 0 | AL13: =AC13*1%+AH13*1% -> 20 | AM13: =AB13-AD13-AF13-AG13-AH13-AI13-AJ13-AK13-AL13 -> 24980
A14: 16 | B14: Factory | C14: IGT Manufacturing | D14: Man1747 | E14: E.. Manikandan | F14: CNC Operator | G14: 31 | H14: 16000 | I14: 8000 | J14: 8000 | K14: 0 | L14: 32000 | M14: 1800 | N14: 0 | O14: 29 | P14: 2 | Q14: 1 | R14: 16000 | S14: 8000 | T14: 8000 | U14: 0 | V14: ='Factory Overtime working'!F5 -> 1066.6667 | W14: 0 | X14: 0 | Y14: 0 | Z14: 0 | AA14: 0 | AB14: =SUM(R14:AA14) -> 33066.667 | AC14: 0 | AD14: 0 | AE14: 0 | AF14: =IF(AB14-AI14>=15000, 1800) -> 1800 | AG14: =ROUNDUP(IF((AB14-AI14)>=21001,0,(AB14-AI14)*0.75%),0) -> 0 | AI14: =L14/G14*Q14 -> 1032.2581 | AJ14: 0 | AK14: 0 | AL14: =AC14*1%+AH14*1%+210 -> 210 | AM14: =AB14-AD14-AF14-AG14-AH14-AI14-AJ14-AK14-AL14 -> 30024.409
A15: 17 | B15: Factory | C15: IGT Manufacturing | D15: Pal1459 | E15: Singara Lakshmanan Palanisamy | F15: Lathe Operator | G15: 31 | H15: 13500 | I15: 6750 | J15: 6750 | K15: 0 | L15: 27000 | M15: 1800 | N15: 0 | O15: 26 | P15: 5 | Q15: 4 | R15: 13500 | S15: 6750 | T15: 6750 | U15: 0 | V15: ='Factory Overtime working'!F6 -> 0 | W15: 0 | X15: 0 | Y15: 0 | Z15: 0 | AA15: 0 | AB15: =SUM(R15:AA15) -> 27000 | AC15: 0 | AD15: 0 | AE15: 0 | AF15: =IF(AB15-AI15>=15000, 1800) -> 1800 | AG15: =ROUNDUP(IF((AB15-AI15)>=21001,0,(AB15-AI15)*0.75%),0) -> 0 | AI15: =L15/G15*Q15 -> 3483.871 | AJ15: 0 | AK15: 0 | AL15: =AC15*1%+AH15*1%+210 -> 210 | AM15: =AB15-AD15-AF15-AG15-AH15-AI15-AJ15-AK15-AL15 -> 21506.129
A16: 18 | B16: Factory | C16: IGT Manufacturing | D16: Pan1362 | E16: M..Pandi | F16: Fitter | G16: 31 | H16: 15500 | I16: 7750 | J16: 7750 | K16: 0 | L16: 31000 | M16: 1800 | N16: 0 | O16: 29 | P16: 2 | Q16: 1 | R16: 15500 | S16: 7750 | T16: 7750 | U16: 0 | V16: ='Factory Overtime working'!F7 -> 3100 | W16: 0 | X16: 0 | Y16: 0 | AA16: 0 | AB16: =SUM(R16:AA16) -> 34100 | AC16: 0 | AD16: 0 | AE16: 0 | AF16: =IF(AB16-AI16>=15000, 1800) -> 1800 | AG16: =ROUNDUP(IF((AB16-AI16)>=21001,0,(AB16-AI16)*0.75%),0) -> 0 | AI16: =L16/G16*Q16 -> 1000 | AJ16: 0 | AK16: 0 | AL16: =AC16*1%+AH16*1%+210 -> 210 | AM16: =AB16-AD16-AF16-AG16-AH16-AI16-AJ16-AK16-AL16 -> 31090
A17: 19 | B17: Factory | C17: IGT Manufacturing | D17: ...1694 | E17: Ramjanam... | F17: Welder | G17: 31 | H17: 13000 | I17: 6500 | J17: 6500 | K17: 0 | L17: 26000 | M17: 1800 | N17: 0 | O17: 30 | P17: 1 | Q17: 0 | R17: 13000 | S17: 6500 | T17: 6500 | U17: 0 | V17: ='Factory Overtime working'!F8 -> 3791.6667 | W17: 0 | X17: 0 | Y17: 0 | AA17: 0 | AB17: =SUM(R17:AA17) -> 29791.667 | AC17: 0 | AD17: 0 | AE17: 0 | AF17: 1800 | AG17: 0 | AI17: =L17/G17*Q17 -> 0 | AJ17: 0 | AK17: 0 | AL17: =AC17*1%+AH17*1%+210 -> 210 | AM17: =AB17-AD17-AF17-AG17-AH17-AI17-AJ17-AK17-AL17 -> 27781.667
A18: 20 | B18: Factory | C18: IGT Manufacturing | D18: Kum1284 | E18: DharmendraKumar | F18: Welder | G18: 31 | H18: 12500 | I18: 6250 | J18: 6250 | K18: 0 | L18: 25000 | M18: 1800 | N18: 0 | O18: 29 | P18: 2 | Q18: 1 | R18: 12500 | S18: 6250 | T18: 6250 | U18: 0 | V18: ='Factory Overtime working'!F9 -> 3645.8333 | W18: 0 | X18: 0 | Y18: 0 | AA18: 0 | AB18: =SUM(R18:AA18) -> 28645.833 | AC18: 0 | AD18: 0 | AE18: 0 | AF18: 1800 | AG18: 0 | AI18: =L18/G18*Q18 -> 806.45161 | AJ18: 0 | AK18: 0 | AL18: =AC18*1%+AH18*1%+210 -> 210 | AM18: =AB18-AD18-AF18-AG18-AH18-AI18-AJ18-AK18-AL18 -> 25829.382
A19: 21 | B19: Factory | C19: IGT Manufacturing | D19: Tha1708 | E19: AjinThavasimuthu | F19: Factory Coordinator | G19: 31 | H19: 15000 | I19: 7500 | J19: 7500 | K19: 0 | L19: 30000 | M19: 1800 | N19: 0 | O19: 22.5 | P19: 8.5 | Q19: 8.5 | R19: 15000 | S19: 7500 | T19: 7500 | U19: 0 | W19: 0 | X19: 0 | Y19: 0 | AA19: 0 | AB19: =SUM(R19:AA19) -> 30000 | AC19: 20000 | AD19: 10000 | AE19: 10000 | AF19: =IF(AB19-AI19>=15000, 1800) -> 1800 | AG19: =ROUNDUP(IF((AB19-AI19)>=21001,0,(AB19-AI19)*0.75%),0) -> 0 | AI19: =L19/G19*Q19 -> 8225.8065 | AJ19: 0 | AK19: 0 | AL19: =AC19*1%+AH19*1%+210 -> 410 | AM19: =AB19-AD19-AF19-AG19-AH19-AI19-AJ19-AK19-AL19 -> 9564.1935 | AO19: Lop deducted fully
A20: 22 | B20: Factory | C20: IGT Manufacturing | D20: ...1958 | E20: Paramasivam... | F20: VMC Operator | G20: 31 | H20: 15500 | I20: 7750 | J20: 7750 | K20: 0 | L20: 31000 | M20: 0 | N20: 0 | O20: 26 | P20: 4 | Q20: 3 | R20: 15500 | S20: 7750 | T20: 7750 | U20: 0 | V20: ='Factory Overtime working'!F11 -> 1033.3333 | W20: 0 | X20: 0 | Y20: 0 | Z20: 0 | AA20: 0 | AB20: =SUM(R20:AA20) -> 32033.333 | AC20: 0 | AD20: 0 | AE20: 0 | AF20: 1800 | AG20: 0 | AI20: =L20/G20*Q20 -> 3000 | AJ20: 0 | AK20: 0 | AL20: 210 | AM20: =AB20-AD20-AF20-AG20-AH20-AI20-AJ20-AK20-AL20 -> 27023.333
A21: 23 | B21: Office | C21: Igreen | D21: Kri1982 | E21: BharathKrishna | F21: CAD Designer | G21: 31 | H21: 9000 | I21: 4500 | J21: 4500 | K21: 0 | L21: 18000 | M21: 1800 | N21: 0 | O21: 27 | P21: 4 | Q21: 0 | R21: 9000 | S21: 4500 | T21: 4500 | U21: 0 | W21: 0 | X21: 0 | Y21: 0 | Z21: 0 | AA21: 0 | AB21: =SUM(R21:AA21) -> 18000 | AC21: 0 | AD21: 0 | AE21: 0 | AF21: 1800 | AG21: =ROUNDUP(IF((AB21-AI21)>=21001,0,(AB21-AI21)*0.75%),0) -> 135 | AI21: =L21/G21*Q21 -> 0 | AJ21: 0 | AK21: 0 | AL21: =AC21*1%+AH21*1%+210 -> 210 | AM21: =AB21-AD21-AF21-AG21-AH21-AI21-AJ21-AK21-AL21 -> 15855 | AO21: No lop deducted to be cut from Main leave
A22: 24 | B22: Factory | C22: IGT Manufacturing | D22: Kum1588 | E22: MotiKumar | F22: Helper | G22: 31 | H22: 7500 | I22: 3750 | J22: 3750 | K22: 0 | L22: 15000 | M22: 0 | N22: 0 | O22: 30 | P22: 1 | Q22: 0 | R22: 7500 | S22: 3750 | T22: 3750 | U22: 0 | V22: ='Factory Overtime working'!F13 -> 2187.5 | W22: 0 | X22: 0 | Y22: 0 | AA22: 0 | AB22: =SUM(R22:AA22) -> 17187.5 | AC22: 0 | AD22: 0 | AE22: 0 | AF22: 1800 | AG22: 0 | AI22: =L22/G22*Q22 -> 0 | AJ22: 0 | AK22: 0 | AL22: 210 | AM22: =AB22-AD22-AF22-AG22-AH22-AI22-AJ22-AK22-AL22 -> 15177.5
A23: 25 | B23: Office | C23: Igreen | D23: Ali1708 | E23: AktarAli | F23: Operator | G23: 31 | H23: 21500 | I23: 10750 | J23: 10750 | K23: 0 | L23: 43000 | M23: 1800 | N23: 0 | O23: 31 | P23: 0 | Q23: 0 | R23: 21500 | S23: 10750 | T23: 10750 | U23: 0 | W23: 0 | X23: 0 | Y23: 0 | AA23: 0 | AB23: =SUM(R23:AA23) -> 43000 | AC23: 0 | AE23: =AC23-AD23 -> 0 | AF23: =IF(AB23-AI23>=15000, 1800) -> 1800 | AG23: =ROUNDUP(IF((AB23-AI23)>=21001,0,(AB23-AI23)*0.75%),0) -> 0 | AI23: 10000 | AJ23: 0 | AK23: 0 | AL23: =AC23*1%+210 -> 210 | AM23: =AB23-AD23-AF23-AG23-AH23-AI23-AJ23-AK23-AL23 -> 30990 | AN23: Fight Ticket Chennai to Bagdogra & return Rs.14957/- is taken as staff welfare . 15 days leave allowed 10 days taken balance 5 days pending | AO23: Holded 10k as instructed by Sara sir
A24: 26 | B24: Office | C24: Igreen | D24: B..1921 | E24: ShajanB.. | F24: Accounts Assistant | G24: 31 | H24: 11250 | I24: 5500 | J24: 3250 | K24: 0 | L24: 20000 | M24: 1800 | N24: 0 | O24: 28 | P24: 3 | Q24: 0 | R24: 11250 | S24: 5500 | T24: 3250 | U24: 0 | W24: 0 | X24: 0 | Y24: 0 | Z24: 0 | AA24: 0 | AB24: =SUM(R24:AA24) -> 20000 | AC24: 0 | AD24: 0 | AE24: 0 | AF24: =IF(AB24-AI24>=15000, 1800) -> 1800 | AG24: =ROUNDUP(IF((AB24-AI24)>=21001,0,(AB24-AI24)*0.75%),0) -> 150 | AI24: =L24/G24*Q24 -> 0 | AJ24: 0 | AK24: 0 | AL24: =AC24*1%+210 -> 210 | AM24: =AB24-AD24-AF24-AG24-AH24-AI24-AJ24-AK24-AL24 -> 17840 | AN24: =17840-17527 -> 313 | AO24: 2500 to be paid as cash | AP24: to be paid in cash
A25: 28 | B25: Office | C25: Igreen | D25: Vee1740 | E25: BagavathiappanVeeralekshmanan | F25: Accounts Assistant | G25: 31 | H25: 10750 | I25: 5500 | J25: 5250 | K25: 0 | L25: 21500 | M25: 1800 | N25: 0 | O25: 27.5 | P25: 3.5 | Q25: 3.5 | R25: 10750 | S25: 5500 | T25: 5250 | U25: 0 | W25: 0 | X25: 0 | Y25: 0 | Z25: 0 | AA25: 0 | AB25: =SUM(R25:AA25) -> 21500 | AC25: 0 | AD25: 0 | AE25: 0 | AF25: =IF(AB25-AI25>=15000, 1800) -> 1800 | AG25: 0 | AI25: =L25/G25*Q25 -> 2427.4194 | AJ25: 0 | AK25: 0 | AL25: =AC25*1%+AH25*1%+210 -> 210 | AM25: =AB25-AD25-AF25-AG25-AH25-AI25-AJ25-AK25-AL25 -> 17062.581 | AO25: Lop deducted fully
A26: 29 | B26: Office | C26: Igreen Transfer | D26: Pra1921 | E26: ArunPrasath A | F26: Sr. Admin Executive | G26: 31 | H26: 12500 | I26: 6250 | J26: 6250 | K26: 0 | L26: 25000 | M26: 0 | N26: 0 | O26: 0 | P26: 31 | Q26: 31 | R26: 12500 | S26: 6250 | T26: 6250 | U26: 0 | X26: 0 | Y26: 0 | Z26: 0 | AA26: 0 | AB26: =SUM(R26:AA26) -> 25000 | AC26: 0 | AD26: 0 | AE26: 0 | AF26: 0 | AG26: 0 | AI26: =L26/G26*Q26 -> 25000 | AJ26: 0 | AK26: 0 | AL26: 0 | AM26: =7500 -> 7500 | AO26: to be released in this salary , 1000rs deducted this month
A27: 30 | B27: Office | C27: Igreen Transfer | D27: S..1459 | E27: SureshS.. | F27: Project Assistant | G27: 31 | H27: 12000 | I27: 6000 | J27: 4000 | K27: 2000 | L27: 24000 | M27: 0 | N27: 0 | O27: 29 | P27: 2 | Q27: 0 | R27: 12000 | S27: 6000 | T27: 4000 | U27: 0 | W27: 2000 | X27: 0 | Y27: 0 | Z27: 0 | AA27: 0 | AB27: =SUM(R27:AA27) -> 24000 | AC27: 8000 | AD27: 2000 | AE27: =AC27-AD27 -> 6000 | AF27: 0 | AG27: 0 | AH27: 1300 | AI27: =L27/G27*Q27 -> 0 | AJ27: 0 | AK27: 0 | AL27: =AC27*1%+AH27*1% -> 93 | AM27: =AB27-AD27-AF27-AG27-AH27-AI27-AJ27-AK27-AL27 -> 20607
A28: 31 | B28: Office | C28: igreen | E28: Srikaliyaraj | G28: 31 | O28: 0 | U28: 0 | AB28: 0 | AC28: 15000 | AD28: 5000 | AE28: =AC28-AD28 -> 10000 | AI28: =L28/G28*Q28 -> 0 | AL28: =AC28*1%+AH28*1% -> 150 | AO28: 20k loan 5k deducted balance 15k
AM29: =SUM(AM2:AM28) -> 655808.07
I30: x | AL30: Oman Salary | AM30: ='OMan salary'!J14 -> 0
AL31: Cash | AM31: =15000+5000+2500+2000 -> 24500
AD32: =#REF!/30*14 -> #REF! | AL32: Labours Salary | AM32: 274621
AM33: =AM29+AM30+AM32+AM31 -> 954929.07
AL38: =34000*18% -> 6120
AL39: 34000
AL40: =AL39+AL38 -> 40120
AM43: =1720000/20*100 -> 8600000
AB44: =25000/30*29 -> 24166.667 | AM44: =8555000*20% -> 1711000

Sheet OMan salary
A1: Dec 25- Jan 26
G2: Gross Salary | I2: Deductions | J2: Net Salary | M2: Pending | N2: Remarks
A3: Sr. No. | B3: Emp. Name | C3: Location | D3: Total Days | E3: OMAN | F3: Leave Days | G3: OMR | H3: Incentive | I3: LOP | J3: OMR | K3: INR
A4: 1 | B4: Anwar | C4: OMAN | D4: 31 | E4: 31 | F4: 0 | G4: =400 -> 400 | H4: 231.4 | I4: 0 | J4: =G4+H4 -> 631.4 | K4: 0 | L4: =J4*225 -> 142065 | M4: 0 | O4: 0
A5: 2 | B5: Sri Kaliaraj B | C5: OMAN | D5: 31 | E5: 26 | F5: 5 | G5: 250 | I5: 40.3 | J5: =G5/31*26 -> 209.67742 | K5: 0 | M5: 0
A6: 3 | B6: Pintu Oraon | C6: OMAN | D6: 31 | E6: 31 | F6: 0 | G6: 200 | I6: 0 | J6: =G6-I6 -> 200 | K6: 0 | L6: =J6*225 -> 45000 | M6: 0
A7: 4 | B7: Richu | C7: OMAN | D7: 31 | E7: 22 | F7: 9 | G7: 300 | I7: 0 | J7: =(G7-I7) -> 300 | K7: 0 | L7: =J7*225 -> 67500
A8: 5 | B8: OMANI Staff | C8: Dummy | D8: 31 | E8: 31 | F8: 0 | G8: 350 | I8: 0 | K8: 0 | L8: =J8*225 -> 0
A9: 6 | B9: Rambilas Oraon | C9: OMAN | D9: 31 | E9: 31 | F9: 0 | G9: 150 | I9: 0 | J9: =G9-I9 -> 150 | L9: =J9*225 -> 33750 | M9: 0
A10: 7 | B10: Bikki rao | C10: OMAN | D10: 31 | E10: 25 | F10: 5 | G10: 700 | I10: =G10*F10/31+700*10/31 -> 338.70968 | J10: =G10-I10 -> 361.29032 | L10: =J10*225 -> 81290.323
A11: 8 | B11: Ali Driver | C11: OMAN | D11: 31 | E11: 29 | F11: 2 | G11: 300 | I11: =G11*F11/31 -> 19.354839 | J11: =G11-I11 -> 280.64516
I12: TOTAL | J12: =SUM(J4:J11) -> 2133.0129 | K12: =SUM(K4:K9) -> 0
L14: =SUM(L4:L10) -> 369605.32 | N14: =L4-15000 -> 127065 | U14: 694790
N15: =N14/2 -> 63532.5 | U15: 847416
U16: 1655280
U17: 724161
U18: 638966
B19: Anwar | C19: 400 | U19: 5157841
B20: Less: Leave | C20: 0
B21: Add: Oman Incentive | C21: 231.4
B22: Total | C22: =C19+C21 -> 631.4
B23: Less: Deduction | C23: 0 | U23: =SUM(U14:U19) -> 9718454
B24: less: Oman need | C24: 50 | U24: =U23*0.1% -> 9718.454
B25: Indian Salary | C25: =C19-C23-C24-C20 -> 350
B26: Indian Rs | C26: =C25*225 -> 78750
B27: Less: Flight Ticket | C27: 0 | D27: over
B28: Salary Payable | C28: =C26-C27 -> 78750 | E28: =C28+C38+C47+C55+C63+C72 -> 348932.5
B32: Richu Thomas | C32: 300
B33: Less: Deduction | C33: 50
B34: less: Oman need | C34: 0
B35: Indian Salary | C35: =C32-C33-C34 -> 250
B36: Indian Rs | C36: =C35*225 -> 56250
B37: Less: Advance
B38: Salary Payable | C38: =C36-C37 -> 56250
B41: Sri Kaliyaraj B | C41: 250
B42: Less: Deduction | C42: =40.3 -> 40.3
B43: less: Oman need | C43: 0
B44: Oman Salary | C44: =C41-C42-C43 -> 209.7
B45: Indian Rs | C45: =C44*225 -> 47182.5
B46: Less: Advance | C46: =5000+150 -> 5150 | D46: Balance 10k
...

Sheet Labour salary
A1: LABOUR SALARY FOR THE MONTH OF JAN-2026
A2: Status | B2: Emp Code | C2: Account No. | D2: Name | E2: Total Present | F2: Gross salary | G2: Days | H2: Leave Days | I2: LOP | J2: Advance | K2: Food allowance | L2: Salary to Pay | M2: Remarks
A3: Active | B3: IGT - H -0010 | C3: 922010030106709 | D3: Satindra Oraon | E3: 31 | F3: 15000 | G3: 31 | H3: 0 | I3: 0 | J3: 0 | K3: 2800 | L3: 17800
A4: Active | B4: IGT - H -0013 | C4: 922010030107083 | D4: Ankit Oraon | E4: 31 | F4: 15000 | G4: 31 | H4: 0 | I4: 0 | J4: 5300 | K4: 2800 | L4: 12500
A5: Active | B5: IGT - H -0014 | C5: 924010027612110 | D5: Sandip Oraon | E5: 31 | F5: 15000 | G5: 31 | H5: 0 | I5: 0 | J5: 1100 | K5: 2800 | L5: 16700
A6: Active | B6: IGT - H -0015 | C6: 921010034495026 | D6: Punay Oraon | E6: 31 | F6: 15000 | G6: 31 | H6: 0 | I6: 0 | J6: 100 | K6: 2800 | L6: 17700
A7: Active | B7: IGT - H -0016 | C7: 920010069989254 | D7: Binay Oraon | E7: 31 | F7: 17000 | G7: 31 | H7: 0 | I7: 0 | J7: 300 | K7: 2800 | L7: 19500
A8: Active | B8: IGT - H -0018 | C8: 923010021147921 | D8: M Manoj Oraon | E8: 31 | F8: 15000 | G8: 31 | H8: 0 | I8: 0 | J8: 300 | K8: 2800 | L8: 17500
A9: Active | B9: IGT - H -0024 | C9: 924010027612343 | D9: Shushil Oraon | E9: 31 | F9: 15000 | G9: 31 | H9: 0 | I9: 0 | J9: 0 | K9: 2800 | L9: 17800
A10: Active | B10: IGT - H -0028 | C10: 923010001167521 | D10: Sunil Baraik | E10: 31 | F10: 15000 | G10: 31 | H10: 0 | I10: 0 | J10: 100 | K10: 2800 | L10: 17700
A11: Active | B11: IGT - H -0030 | D11: Pila Oraon | E11: 0 | F11: 15000 | G11: 31 | H11: 31 | I11: 15000 | J11: 900 | K11: 2800 | L11: 1900
A12: Active | B12: IGT - H -0031 | C12: 924010027621392 | D12: Ashok Oraon | E12: 31 | F12: 15000 | G12: 31 | H12: 0 | I12: 0 | J12: 0 | K12: 2800 | L12: 17800
A13: Active | B13: IGT - H -0033 | D13: Bikram Oraon | E13: 31 | F13: 15000 | G13: 31 | H13: 0 | I13: 0 | J13: 100 | K13: 2800 | L13: 17700
A14: Active | B14: IGT - H -0034 | D14: Panchu Oraon | E14: 31 | F14: 15000 | G14: 31 | H14: 0 | I14: 0 | J14: 100 | K14: 2800 | L14: 17700
A15: Active | B15: IGT - H -0040 | D15: Jatru Oraon | E15: 31 | F15: 15000 | G15: 31 | H15: 0 | I15: 0 | J15: 2100 | K15: 2800 | L15: 15700
A16: Active | D16: Kalai Selvi | E16: 30 | F16: 4000 | G16: 31 | H16: 1 | I16: 129.03226 | J16: 0 | K16: 0 | L16: 3870.9677
A17: Active | B17: IGT - H -0043 | D17: Jeetwahan Oraon | E17: 31 | F17: 15000 | G17: 31 | H17: 0 | I17: 0 | J17: 100 | K17: 2800 | L17: 17700
A18: Active | B18: IGT - H -0044 | C18: 8217550949 | D18: Basdev Oraon | E18: 31 | F18: 15000 | G18: 31 | H18: 0 | I18: 0 | J18: 0 | K18: 2800 | L18: 17800
A19: Active | B19: IGT - H -0045 | C19: 8217637923 | D19: Amar Oraon | E19: 31 | F19: 15000 | G19: 31 | H19: 0 | I19: 0 | J19: 0 | K19: 2800 | L19: 17800
A20: Active | B20: IGT - H -0046 | D20: Raju Oraon | E20: 0 | F20: 15000 | G20: 31 | H20: 31 | I20: 15000 | J20: 900 | K20: 2800 | L20: 1900
A21: Active | B21: IGT - H -0048 | D21: Sant Kumar Oraon | E21: 0 | F21: 15000 | G21: 31 | H21: 31 | I21: 15000 | J21: 900 | K21: 2800 | L21: 1900
L22: 268970.97

Sheet Factory Overtime working
A2: S.no | B2: Name | C2: OT HOURS | D2: GROSS SALARU | E2: PER HOUR | F2: OT AMOUNT | G2: LEAVE | H2: Deducted
A3: 1 | B3: Kannan P | C3: 30 | D3: =SUM('Salary Jan 2026'!R9:T9) -> 20000 | E3: =D3/30/8 -> 83.333333 | F3: =C3*E3 -> 2500 | G3: 5
A4: 2 | B4: Sivarajan Shanmugam | D4: =SUM('Salary Jan 2026'!R12:T12) -> 37000 | E4: =D4/30/8 -> 154.16667 | F4: =C4*E4 -> 0 | G4: 1 | H4: 0
A5: 3 | B5: E Manikandan | C5: 8 | D5: =SUM('Salary Jan 2026'!R14:T14) -> 32000 | E5: =D5/30/8 -> 133.33333 | F5: =C5*E5 -> 1066.6667 | G5: 1 | H5: 0
A6: 4 | B6: Singara Lakshmanan Palanisamy | C6: 0 | D6: 27000 | E6: =D6/30/8 -> 112.5 | F6: =C6*E6 -> 0 | G6: 4.5 | H6: 3.5
A7: 5 | B7: M.Pandi | C7: 24 | D7: =SUM('Salary Jan 2026'!R16:T16) -> 31000 | E7: =D7/30/8 -> 129.16667 | F7: =C7*E7 -> 3100 | G7: 2 | H7: 0
A8: 6 | B8: Ramjanam | C8: 35 | D8: =SUM('Salary Jan 2026'!R17:T17) -> 26000 | E8: =D8/30/8 -> 108.33333 | F8: =C8*E8 -> 3791.6667 | G8: 0 | H8: 0
A9: 7 | B9: Dharmendra Kumar | C9: 35 | D9: =SUM('Salary Jan 2026'!R18:T18) -> 25000 | E9: =D9/30/8 -> 104.16667 | F9: =C9*E9 -> 3645.8333 | G9: 0 | H9: 0
A10: 8 | B10: Ajin Thavasimuthu | C10: 10 | D10: =SUM('Salary Jan 2026'!R19:T19) -> 30000 | E10: =D10/30/8 -> 125 | F10: 0 | G10: 2 | H10: 1
A11: 9 | B11: Paramasivam | C11: 8 | D11: =SUM('Salary Jan 2026'!R20:T20) -> 31000 | E11: =D11/30/8 -> 129.16667 | F11: =C11*E11 -> 1033.3333 | G11: 2 | H11: 1
A12: 10 | B12: Bharath Krishna J S | D12: =SUM('Salary Jan 2026'!R21:T21) -> 18000 | E12: =D12/30/8 -> 75 | G12: 2 | H12: 1.5
A13: 11 | B13: Moti Kumar | C13: 35 | D13: =SUM('Salary Jan 2026'!R22:T22) -> 15000 | E13: =D13/30/8 -> 62.5 | F13: =E13*C13 -> 2187.5 | G13: 0 | H13: 0
G14: 0 | H14: 0

Sheet Incentive & Cummulative Incenti
A1: Category 1 | F1: SECTOR
A2: Incentive for Own Machine Projects
A3: Product | B3: Operator | C3: Tracker | D3: Supervisor | E3: Incentive for Operator , Trackers Supervisors (Meters worked * Rate specified) | F3: SERVICE SECTOR
A4: Duct | B4: 4 | C4: 4 | D4: 2
A5: Eb LT cable 240 sqmm
A6: EB Cable 11kv 120sqmm | B6: 6 | C6: 6 | D6: 3
A7: EB Cable 11kv 300sqmm | B7: 8 | C7: 8 | D7: 3
A8: EB Cable 11kv double | B8: 12 | C8: 12 | D8: 4
A9: EB Cable 33kv 3 cable | B9: 12 | C9: 12 | D9: 4
A10: EB Cable 33kv single cable | B10: 8 | C10: 8 | D10: 3
A11: MSPIPE EB /TWAD | B11: 125 | C11: 125 | D11: 50
A12: HDPE 110 | B12: 25 | C12: 25 | D12: 10
A13: HDPE 160 to 250 dia | B13: 50 | C13: 50 | D13: 25
A14: HDPE 250 dia above 500mm | B14: 75 | C14: 75 | D14: 35
A15: HDPE above 500mm | B15: 125 | C15: 125 | D15: 50
A16: GAS Pipeline 100mm-250mm | B16: 40 | C16: 40 | D16: 20
A17: GAS Pipeline 250mm- 400mm | B17: 60 | C17: 60 | D17: 30
... A19: GAS Pipeline above500mm | B19: 125 | C19: 125 | D19: 50
A20: (Meters worked * Rate specified) /2 will be provided this month , balance will be added in the cummulative incentive
A23: Cummulative Incentive | B23: Every month 1/2 amount holded will be given in the quarter . Example, December 1/2, January 1/2, February 1/2 will be given in March Salary as cummulative incentive
A27: Category 2
A28: Incentive for Subcontracts/other machine used for our works 1/2 of the amount mentioned in the Rate ((Meters worked * Rate specified) /2)) No cummilative for othe machine works .
A30: Category 3
A31: Project Incentive | B31: 0.4% of the Project value without GST once the Payment credited in our Bank account only for own Projects not for Subcontracts. Manager should have worked in the project to get the incentive( Project value*0.4%)
A37: Category 4
A38: Over Time | B38: Extra Payment for extra Hours worked ,however check in time and check out time must be monitored purpose of extra work shall be noted (extra hours worked * Per hour Salary) ( Per Hour salary = Gross Salary / 30/31 days/8 Hours) | F38: Factory /Manufacturing Sector
A43: We might add new type of Incentive scheme as well

Sheet Green Thanks & Bonus & Travel
A1: Green Thanks
A3: 1. Green Thanks may be given by one employee to another employee as a token of appreciation.
A5: 2. A maximum limit per quarter will be fixed by the Management.
A7: 3. The reason for awarding Green Thanks must be clearly mentioned.
A9: 4. All Green Thanks awards are subject to Management approval.
A13: Bonus
A15: 1. During the Diwali period, a performance bonus may be provided by the Management based on the employee’s salary and performance.
A17: 2. The decision regarding the bonus amount and eligibility rests solely with the Management.
A21: Travel Allowance
A23: 1. Travel allowance will be provided to employees based on their travel requirements and eligibility as defined by the Management.

Sheet Leave policy
A2: KINDS OF LEAVE POLICY
A4: 1. Casual Leave (CL)
A6: Purpose: Personal work, emergencies, short absences
A9: Carry Forward: ❌ Not allowed
A11: Encashment: ❌ Not allowed
A13: Approval: Prior approval from reporting manager to be done before availing the leave (1 day before)
A17: 2. Sick Leave (SL)
A19: Purpose: Illness or medical reasons
A22: Carry Forward: ❌ Not allowed
A24: Encashment: ❌ Not allowed
A26: Medical Certificate: Required if more than 2 consecutive days with companies DOCTOR approval
A30: 3. Earned Leave / Privilege Leave (EL / PL) | F30: hide this
A32: Purpose: Planned long leave
A35: Carry Forward: ✅ Allowed (up to 45 days)
A37: Encashment: ✅ Allowed at separation / as per policy
A39: Approval: Apply minimum 7 days in advance
A43: 4. Loss of Pay (LOP)
A45: Applicable when leave balance is exhausted or leave is unauthorized and during Probation Period
A47: Salary will be deducted proportionately
A49: Affects PF, ESI & other statutory calculations
A53: 5. Compensatory Off (Comp-Off)
A55: Applicable for working on weekly off / declared holiday
A57: Must be approved in advance
A59: Validity: Use within 30 days
... A115: 📊 SUMMARY TABLE (EXCEL READY)
A117: Leave Type | B117: Days / Year | C117: Carry Forward | D117: Encashment | E117: Remarks
A118: Casual Leave | C118: No | D118: No | E118: Short absences
A119: Sick Leave | C119: No | D119: No | E119: Medical proof if >2 days
A120: Earned Leave | C120: Yes (45 max) | D120: Yes | E120: Planned leave | F120: Not applicable now
A121: LOP | B121: NA | C121: NA | D121: NA | E121: Salary deduction
A122: Comp-Off | B122: As applicable | C122: No | D122: No | E122: Use within 30 days
A123: Maternity Leave | B123: 26 weeks | C123: NA | D123: NA | E123: Statutory
A124: Paternity Leave | B124: 5 | C124: No | D124: No | E124: Optional
A125: Marriage Leave | B125: 3 | C125: No | D125: No | E125: Optional
A126: Bereavement Leave | B126: 3 | C126: No | D126: No | E126: Immediate family
A127: Holidays | B127: 10–12 | C127: NA | D127: NA | E127: Company Declared

Sheet STATUTORY COMPLAINCE
A2: 1. Provident Fund (PF)
A4: PF is applicable only to selected employees.
A6: If Basic Salary > ₹15,000
A7: → PF is calculated as ₹15,000 × 12% = ₹1,800
A9: If Basic Salary ≤ ₹15,000
A10: → PF is calculated as Basic Salary × 12%
A12: Loss of Pay (LOP) will be deducted while calculating the gross salary, and PF will be calculated on the eligible basic salary after LOP adjustment.
A16: 2. Employees’ State Insurance (ESI)
A18: Employees selected for PF will be automatically considered for ESI, subject to eligibility.
A20: If Gross Salary ≤ ₹21,000, ESI is applicable.
A22: Employee ESI contribution: 0.75% of Gross Salary
A24: If Gross Salary > ₹21,000, ESI is not applicable.
... A43: Income tax slab rates are subject to change every year as per government notifications.
A48: Component | B48: Applicability | C48: Calculation | D48: Remarks
A49: PF | B49: Selected Employees | C49: 12% of ₹15,000 (if salary > ₹15k) or 12% of actual basic | D49: LOP applicable
A50: ESI | B50: Salary ≤ ₹21,000 | C50: 0.75% of Gross Salary | D50: LOP applicable
A51: Professional Tax | B51: PF / ESI Employees | C51: ₹1,250 per half-year | D51: As per state rules
A52: TDS | B52: All applicable employees | C52: As per IT slab | D52: Changes yearly

Sheet Loan&adv , deductions, Contribu
A1: Loans and Advances
A3: 1. Employees are eligible to apply for a loan only after completing a minimum of 18 months of continuous service.
A5: 2. Loan eligibility and amount will be determined based on the employee’s salary and necessity.
A7: 3. An interest rate of 1% per month will be charged on the outstanding principal amount.
A9: 4. Salary advances, if approved, will be limited to a maximum of ₹5,000.
A11: 5. Approved advances will be deducted from the subsequent salary.
A13: 6. An interest rate of 1% will be applicable on the advance amount.
A15: 7. Advances are provided based on necessity, at Management’s discretion, and no additional eligibility criteria apply.
A19: Deductions
A21: 1. Any act or omission by an employee that results in financial loss to the Company may attract salary deductions.
A23: 2. The deduction amount will be proportionate to the monetary loss incurred and decided by the Management.
A27: Contributions
A29: 1. Contributions made towards staff welfare to support another employee during emergency situations may be deducted from salary, subject to employee consent and Management approval.
